Workbook

Sheet Data Entry
A2: Yom | B2: Art no. | C2: Item | D2: Quality | E2: Supplier | F2: Description | G2: Cost | H2: Increase | I2: Expenses | J2: Total Cost | K2: Net Price Credit | L2: Wsp | M2: Mrp | N2: Net Cash | O2: South | P2: Amazon | Q2: With Box | S2: Value | T2: Box Price for pc. | W2: Box price | X2: Box price | AD2: Item | AH2: Price
A3: 2026 | B3: 203 | C3: shawl | D3: Kashmiri | F3: shahtoosh | G3: 205 | I3: 85 | J3: =IF(SUMIF(G3:I3,"<>")=0,"",SUM(G3:I3)) -> 290 | K3: =IF(ISNUMBER(L3), IF(CEILING(ROUND(L3*0.95,2),5)=420, 425, CEILING(ROUND(L3*0.95,2),5) ), "" ) -> 380 | L3: =IF(ISNUMBER(J3), IF(CEILING(ROUND(J3*1.35,2),5)=420, 425, CEILING(ROUND(J3*1.35,2),5) ), "" ) -> 395 | M3: =IF(AND(ISNUMBER(J3),ISNUMBER(G3)), IF( CEILING( ROUND((J3*1.5) * IF(J3*1.5 <= 2500, 1.05, 1.18), 2), IF(ROUND((J3*1.5) * IF(J3*1.5 <= 2500, 1.05, 1.18), 2) < 2500, 25, 50) )=420, 425, CEILING( ROUND((J3*1.5) * IF(J3*1.5 <= 2500, 1.05, 1.18), 2), IF(ROUND((J3*1.5) * IF(J3*1.5 <= 2500, 1.05, 1.18), 2) < 2500, 25, 50) ) ), "" ) -> 475 | N3: =IF(ISNUMBER(G3), CEILING(ROUND(L3*0.92,2),5), "") -> 365 | O3: =IF(ISNUMBER(L3), IF(CEILING(ROUND(L3*1.07,2),5)=420, 425, CEILING(ROUND(L3*1.07,2),5) ), "" ) -> 425 | P3: =IF((((G3*1.5)+50)/0.835)<2500, MROUND(((((G3*1.5)+50)/0.835)*1.05)*2,10), MROUND(((((G3*1.5)+50)/0.835)*1.18)*2,10)) -> 900 | Q3: =IF($S$3="","", MROUND( IF($S$3="m", IF($T$3=1, Price35[[#This Row],[Mrp]]+$W$4, Price35[[#This Row],[Mrp]]+$X$4), IF($S$3="nc", IF($T$3=1, Price35[[#This Row],[Net Cash]]+$W$5, Price35[[#This Row],[Net Cash]]+$X$5), IF($S$3="npc", IF($T$3=1, Price35[[#This Row],[Net Price Credit]]+$W$6, Price35[[#This Row],[Net Price Credit]]+$X$6), IF($S$3="w", IF($T$3=1, Price35[[#This Row],[Wsp]]+$W$6, Price35[[#This Row],[Wsp]]+$X$6), "")))), 10)) -> 550 | S3: m | T3: 1 | W3: 1 | X3: 2 | AD3: cashmilon cloth | AH3: 440/- kg
A4: 2026 | B4: 208 | C4: shawl | D4: Kashmiri | F4: variety | G4: 205 | I4: 160 | J4: =IF(SUMIF(G4:I4,"<>")=0,"",SUM(G4:I4)) -> 365 | K4: =IF(ISNUMBER(L4), IF(CEILING(ROUND(L4*0.95,2),5)=420, 425, CEILING(ROUND(L4*0.95,2),5) ), "" ) -> 475 | L4: =IF(ISNUMBER(J4), IF(CEILING(ROUND(J4*1.35,2),5)=420, 425, CEILING(ROUND(J4*1.35,2),5) ), "" ) -> 495 | M4: =IF(AND(ISNUMBER(J4),ISNUMBER(G4)), IF( CEILING( ROUND((J4*1.5) * IF(J4*1.5 <= 2500, 1.05, 1.18), 2), IF(ROUND((J4*1.5) * IF(J4*1.5 <= 2500, 1.05, 1.18), 2) < 2500, 25, 50) )=420, 425, CEILING( ROUND((J4*1.5) * IF(J4*1.5 <= 2500, 1.05, 1.18), 2), IF(ROUND((J4*1.5) * IF(J4*1.5 <= 2500, 1.05, 1.18), 2) < 2500, 25, 50) ) ), "" ) -> 575 | N4: =IF(ISNUMBER(G4), CEILING(ROUND(L4*0.92,2),5), "") -> 460 | O4: =IF(ISNUMBER(L4), IF(CEILING(ROUND(L4*1.07,2),5)=420, 425, CEILING(ROUND(L4*1.07,2),5) ), "" ) -> 530 | P4: =IF((((G4*1.5)+50)/0.835)<2500, MROUND(((((G4*1.5)+50)/0.835)*1.05)*2,10), MROUND(((((G4*1.5)+50)/0.835)*1.18)*2,10)) -> 900 | Q4: =IF($S$3="","", MROUND( IF($S$3="m", IF($T$3=1, Price35[[#This Row],[Mrp]]+$W$4, Price35[[#This Row],[Mrp]]+$X$4), IF($S$3="nc", IF($T$3=1, Price35[[#This Row],[Net Cash]]+$W$5, Price35[[#This Row],[Net Cash]]+$X$5), IF($S$3="npc", IF($T$3=1, Price35[[#This Row],[Net Price Credit]]+$W$6, Price35[[#This Row],[Net Price Credit]]+$X$6), IF($S$3="w", IF($T$3=1, Price35[[#This Row],[Wsp]]+$W$6, Price35[[#This Row],[Wsp]]+$X$6), "")))), 10)) -> 650 | W4: 70 | X4: 35 | Y4: m=mrp | AD4: s/s pure dyed | AH4: 2500/-
A5: 2026 | B5: 215 | C5: shawl | D5: Kashmiri | F5: multihead neem dour 350 gm | G5: 205 | I5: 265 | J5: =IF(SUMIF(G5:I5,"<>")=0,"",SUM(G5:I5)) -> 470 | K5: =IF(ISNUMBER(L5), IF(CEILING(ROUND(L5*0.95,2),5)=420, 425, CEILING(ROUND(L5*0.95,2),5) ), "" ) -> 605 | L5: =IF(ISNUMBER(J5), IF(CEILING(ROUND(J5*1.35,2),5)=420, 425, CEILING(ROUND(J5*1.35,2),5) ), "" ) -> 635 | M5: =IF(AND(ISNUMBER(J5),ISNUMBER(G5)), IF( CEILING( ROUND((J5*1.5) * IF(J5*1.5 <= 2500, 1.05, 1.18), 2), IF(ROUND((J5*1.5) * IF(J5*1.5 <= 2500, 1.05, 1.18), 2) < 2500, 25, 50) )=420, 425, CEILING( ROUND((J5*1.5) * IF(J5*1.5 <= 2500, 1.05, 1.18), 2), IF(ROUND((J5*1.5) * IF(J5*1.5 <= 2500, 1.05, 1.18), 2) < 2500, 25, 50) ) ), "" ) -> 750 | N5: =IF(ISNUMBER(G5), CEILING(ROUND(L5*0.92,2),5), "") -> 585 | O5: =IF(ISNUMBER(L5), IF(CEILING(ROUND(L5*1.07,2),5)=420, 425, CEILING(ROUND(L5*1.07,2),5) ), "" ) -> 680 | P5: =IF((((G5*1.5)+50)/0.835)<2500, MROUND(((((G5*1.5)+50)/0.835)*1.05)*2,10), MROUND(((((G5*1.5)+50)/0.835)*1.18)*2,10)) -> 900 | Q5: =IF($S$3="","", MROUND( IF($S$3="m", IF($T$3=1, Price35[[#This Row],[Mrp]]+$W$4, Price35[[#This Row],[Mrp]]+$X$4), IF($S$3="nc", IF($T$3=1, Price35[[#This Row],[Net Cash]]+$W$5, Price35[[#This Row],[Net Cash]]+$X$5), IF($S$3="npc", IF($T$3=1, Price35[[#This Row],[Net Price Credit]]+$W$6, Price35[[#This Row],[Net Price Credit]]+$X$6), IF($S$3="w", IF($T$3=1, Price35[[#This Row],[Wsp]]+$W$6, Price35[[#This Row],[Wsp]]+$X$6), "")))), 10)) -> 820 | W5: 56 | X5: 28 | Y5: nc=net cash | AD5: s/s pure white | AH5: 2300/-
A6: 2026 | B6: 216 | C6: shawl | D6: Kashmiri | F6: multihead variety new | G6: 205 | I6: 223 | J6: =IF(SUMIF(G6:I6,"<>")=0,"",SUM(G6:I6)) -> 428 | K6: =IF(ISNUMBER(L6), IF(CEILING(ROUND(L6*0.95,2),5)=420, 425, CEILING(ROUND(L6*0.95,2),5) ), "" ) -> 555 | L6: =IF(ISNUMBER(J6), IF(CEILING(ROUND(J6*1.35,2),5)=420, 425, CEILING(ROUND(J6*1.35,2),5) ), "" ) -> 580 | M6: =IF(AND(ISNUMBER(J6),ISNUMBER(G6)), IF( CEILING( ROUND((J6*1.5) * IF(J6*1.5 <= 2500, 1.05, 1.18), 2), IF(ROUND((J6*1.5) * IF(J6*1.5 <= 2500, 1.05, 1.18), 2) < 2500, 25, 50) )=420, 425, CEILING( ROUND((J6*1.5) * IF(J6*1.5 <= 2500, 1.05, 1.18), 2), IF(ROUND((J6*1.5) * IF(J6*1.5 <= 2500, 1.05, 1.18), 2) < 2500, 25, 50) ) ), "" ) -> 675 | N6: =IF(ISNUMBER(G6), CEILING(ROUND(L6*0.92,2),5), "") -> 535 | O6: =IF(ISNUMBER(L6), IF(CEILING(ROUND(L6*1.07,2),5)=420, 425, CEILING(ROUND(L6*1.07,2),5) ), "" ) -> 625 | P6: =IF((((G6*1.5)+50)/0.835)<2500, MROUND(((((G6*1.5)+50)/0.835)*1.05)*2,10), MROUND(((((G6*1.5)+50)/0.835)*1.18)*2,10)) -> 900 | Q6: =IF($S$3="","", MROUND( IF($S$3="m", IF($T$3=1, Price35[[#This Row],[Mrp]]+$W$4, Price35[[#This Row],[Mrp]]+$X$4), IF($S$3="nc", IF($T$3=1, Price35[[#This Row],[Net Cash]]+$W$5, Price35[[#This Row],[Net Cash]]+$X$5), IF($S$3="npc", IF($T$3=1, Price35[[#This Row],[Net Price Credit]]+$W$6, Price35[[#This Row],[Net Price Credit]]+$X$6), IF($S$3="w", IF($T$3=1, Price35[[#This Row],[Wsp]]+$W$6, Price35[[#This Row],[Wsp]]+$X$6), "")))), 10)) -> 750 | W6: 58 | X6: 29 | Y6: npc= net credit | AD6: fine wool dyed | AH6: 3600/-
A7: 2026 | B7: 291 | C7: shawl | D7: Kashmiri | F7: shahtoosh 50 *100 | G7: 285 | I7: 375 | J7: =IF(SUMIF(G7:I7,"<>")=0,"",SUM(G7:I7)) -> 660 | K7: =IF(ISNUMBER(L7), IF(CEILING(ROUND(L7*0.95,2),5)=420, 425, CEILING(ROUND(L7*0.95,2),5) ), "" ) -> 855 | L7: =IF(ISNUMBER(J7), IF(CEILING(ROUND(J7*1.35,2),5)=420, 425, CEILING(ROUND(J7*1.35,2),5) ), "" ) -> 895 | M7: =IF(AND(ISNUMBER(J7),ISNUMBER(G7)), IF( CEILING( ROUND((J7*1.5) * IF(J7*1.5 <= 2500, 1.05, 1.18), 2), IF(ROUND((J7*1.5) * IF(J7*1.5 <= 2500, 1.05, 1.18), 2) < 2500, 25, 50) )=420, 425, CEILING( ROUND((J7*1.5) * IF(J7*1.5 <= 2500, 1.05, 1.18), 2), IF(ROUND((J7*1.5) * IF(J7*1.5 <= 2500, 1.05, 1.18), 2) < 2500, 25, 50) ) ), "" ) -> 1050 | N7: =IF(ISNUMBER(G7), CEILING(ROUND(L7*0.92,2),5), "") -> 825 | O7: =IF(ISNUMBER(L7), IF(CEILING(ROUND(L7*1.07,2),5)=420, 425, CEILING(ROUND(L7*1.07,2),5) ), "" ) -> 960 | P7: =IF((((G7*1.5)+50)/0.835)<2500, MROUND(((((G7*1.5)+50)/0.835)*1.05)*2,10), MROUND(((((G7*1.5)+50)/0.835)*1.18)*2,10)) -> 1200 | Q7: =IF($S$3="","", MROUND( IF($S$3="m", IF($T$3=1, Price35[[#This Row],[Mrp]]+$W$4, Price35[[#This Row],[Mrp]]+$X$4), IF($S$3="nc", IF($T$3=1, Price35[[#This Row],[Net Cash]]+$W$5, Price35[[#This Row],[Net Cash]]+$X$5), IF($S$3="npc", IF($T$3=1, Price35[[#This Row],[Net Price Credit]]+$W$6, Price35[[#This Row],[Net Price Credit]]+$X$6), IF($S$3="w", IF($T$3=1, Price35[[#This Row],[Wsp]]+$W$6, Price35[[#This Row],[Wsp]]+$X$6), "")))), 10)) -> 1120 | W7: 60 | X7: 30 | Y7: W = WSP | AD7: fine wool white | AH7: 3400/-
A8: 2026 | B8: 292 | C8: shawl | D8: Kashmiri | F8: c.n.d 50 * 100 cashmilon | G8: 285 | I8: 375 | J8: =IF(SUMIF(G8:I8,"<>")=0,"",SUM(G8:I8)) -> 660 | K8: =IF(ISNUMBER(L8), IF(CEILING(ROUND(L8*0.95,2),5)=420, 425, CEILING(ROUND(L8*0.95,2),5) ), "" ) -> 855 | L8: =IF(ISNUMBER(J8), IF(CEILING(ROUND(J8*1.35,2),5)=420, 425, CEILING(ROUND(J8*1.35,2),5) ), "" ) -> 895 | M8: =IF(AND(ISNUMBER(J8),ISNUMBER(G8)), IF( CEILING( ROUND((J8*1.5) * IF(J8*1.5 <= 2500, 1.05, 1.18), 2), IF(ROUND((J8*1.5) * IF(J8*1.5 <= 2500, 1.05, 1.18), 2) < 2500, 25, 50) )=420, 425, CEILING( ROUND((J8*1.5) * IF(J8*1.5 <= 2500, 1.05, 1.18), 2), IF(ROUND((J8*1.5) * IF(J8*1.5 <= 2500, 1.05, 1.18), 2) < 2500, 25, 50) ) ), "" ) -> 1050 | N8: =IF(ISNUMBER(G8), CEILING(ROUND(L8*0.92,2),5), "") -> 825 | O8: =IF(ISNUMBER(L8), IF(CEILING(ROUND(L8*1.07,2),5)=420, 425, CEILING(ROUND(L8*1.07,2),5) ), "" ) -> 960 | P8: =IF((((G8*1.5)+50)/0.835)<2500, MROUND(((((G8*1.5)+50)/0.835)*1.05)*2,10), MROUND(((((G8*1.5)+50)/0.835)*1.18)*2,10)) -> 1200 | Q8: =IF($S$3="","", MROUND( IF($S$3="m", IF($T$3=1, Price35[[#This Row],[Mrp]]+$W$4, Price35[[#This Row],[Mrp]]+$X$4), IF($S$3="nc", IF($T$3=1, Price35[[#This Row],[Net Cash]]+$W$5, Price35[[#This Row],[Net Cash]]+$X$5), IF($S$3="npc", IF($T$3=1, Price35[[#This Row],[Net Price Credit]]+$W$6, Price35[[#This Row],[Net Price Credit]]+$X$6), IF($S$3="w", IF($T$3=1, Price35[[#This Row],[Wsp]]+$W$6, Price35[[#This Row],[Wsp]]+$X$6), "")))), 10)) -> 1120 | AD8: 2/72 white | AH8: 1075/-
B9: 101 | C9: shawl | D9: Wool | F9: plain 40 x 80 | G9: 380 | I9: 20 | J9: =IF(SUMIF(G9:I9,"<>")=0,"",SUM(G9:I9)) -> 400 | K9: =IF(ISNUMBER(L9), IF(CEILING(ROUND(L9*0.95,2),5)=420, 425, CEILING(ROUND(L9*0.95,2),5) ), "" ) -> 515 | L9: =IF(ISNUMBER(J9), IF(CEILING(ROUND(J9*1.35,2),5)=420, 425, CEILING(ROUND(J9*1.35,2),5) ), "" ) -> 540 | M9: =IF(AND(ISNUMBER(J9),ISNUMBER(G9)), IF( CEILING( ROUND((J9*1.5) * IF(J9*1.5 <= 2500, 1.05, 1.18), 2), IF(ROUND((J9*1.5) * IF(J9*1.5 <= 2500, 1.05, 1.18), 2) < 2500, 25, 50) )=420, 425, CEILING( ROUND((J9*1.5) * IF(J9*1.5 <= 2500, 1.05, 1.18), 2), IF(ROUND((J9*1.5) * IF(J9*1.5 <= 2500, 1.05, 1.18), 2) < 2500, 25, 50) ) ), "" ) -> 650 | N9: =IF(ISNUMBER(G9), CEILING(ROUND(L9*0.92,2),5), "") -> 500 | O9: =IF(ISNUMBER(L9), IF(CEILING(ROUND(L9*1.07,2),5)=420, 425, CEILING(ROUND(L9*1.07,2),5) ), "" ) -> 580 | P9: =IF((((G9*1.5)+50)/0.835)<2500, MROUND(((((G9*1.5)+50)/0.835)*1.05)*2,10), MROUND(((((G9*1.5)+50)/0.835)*1.18)*2,10)) -> 1560 | Q9: =IF($S$3="","", MROUND( IF($S$3="m", IF($T$3=1, Price35[[#This Row],[Mrp]]+$W$4, Price35[[#This Row],[Mrp]]+$X$4), IF($S$3="nc", IF($T$3=1, Price35[[#This Row],[Net Cash]]+$W$5, Price35[[#This Row],[Net Cash]]+$X$5), IF($S$3="npc", IF($T$3=1, Price35[[#This Row],[Net Price Credit]]+$W$6, Price35[[#This Row],[Net Price Credit]]+$X$6), IF($S$3="w", IF($T$3=1, Price35[[#This Row],[Wsp]]+$W$6, Price35[[#This Row],[Wsp]]+$X$6), "")))), 10)) -> 720 | AD9: 2/72 dyed | AH9: 1125/-
B10: 102 | C10: shawl | D10: wool | E10: Usha | F10: s.s tape 40 | G10: 380 | I10: 15 | J10: =IF(SUMIF(G10:I10,"<>")=0,"",SUM(G10:I10)) -> 395 | K10: =IF(ISNUMBER(L10), IF(CEILING(ROUND(L10*0.95,2),5)=420, 425, CEILING(ROUND(L10*0.95,2),5) ), "" ) -> 510 | L10: =IF(ISNUMBER(J10), IF(CEILING(ROUND(J10*1.35,2),5)=420, 425, CEILING(ROUND(J10*1.35,2),5) ), "" ) -> 535 | M10: =IF(AND(ISNUMBER(J10),ISNUMBER(G10)), IF( CEILING( ROUND((J10*1.5) * IF(J10*1.5 <= 2500, 1.05, 1.18), 2), IF(ROUND((J10*1.5) * IF(J10*1.5 <= 2500, 1.05, 1.18), 2) < 2500, 25, 50) )=420, 425, CEILING( ROUND((J10*1.5) * IF(J10*1.5 <= 2500, 1.05, 1.18), 2), IF(ROUND((J10*1.5) * IF(J10*1.5 <= 2500, 1.05, 1.18), 2) < 2500, 25, 50) ) ), "" ) -> 625 | N10: =IF(ISNUMBER(G10), CEILING(ROUND(L10*0.92,2),5), "") -> 495 | O10: =IF(ISNUMBER(L10), IF(CEILING(ROUND(L10*1.07,2),5)=420, 425, CEILING(ROUND(L10*1.07,2),5) ), "" ) -> 575 | P10: =IF((((G10*1.5)+50)/0.835)<2500, MROUND(((((G10*1.5)+50)/0.835)*1.05)*2,10), MROUND(((((G10*1.5)+50)/0.835)*1.18)*2,10)) -> 1560 | Q10: =IF($S$3="","", MROUND( IF($S$3="m", IF($T$3=1, Price35[[#This Row],[Mrp]]+$W$4, Price35[[#This Row],[Mrp]]+$X$4), IF($S$3="nc", IF($T$3=1, Price35[[#This Row],[Net Cash]]+$W$5, Price35[[#This Row],[Net Cash]]+$X$5), IF($S$3="npc", IF($T$3=1, Price35[[#This Row],[Net Price Credit]]+$W$6, Price35[[#This Row],[Net Price Credit]]+$X$6), IF($S$3="w", IF($T$3=1, Price35[[#This Row],[Wsp]]+$W$6, Price35[[#This Row],[Wsp]]+$X$6), "")))), 10)) -> 700
A11: 2026 | B11: 150 | C11: Lohi | D11: Fine Wool | E11: ankur | F11: fine wool 270 gm | G11: 970 | H11: 300 | I11: 60 | J11: =IF(SUMIF(G11:I11,"<>")=0,"",SUM(G11:I11)) -> 1330 | K11: =IF(ISNUMBER(L11), IF(CEILING(ROUND(L11*0.95,2),5)=420, 425, CEILING(ROUND(L11*0.95,2),5) ), "" ) -> 1710 | L11: =IF(ISNUMBER(J11), IF(CEILING(ROUND(J11*1.35,2),5)=420, 425, CEILING(ROUND(J11*1.35,2),5) ), "" ) -> 1800 | M11: =IF(AND(ISNUMBER(J11),ISNUMBER(G11)), IF( CEILING( ROUND((J11*1.5) * IF(J11*1.5 <= 2500, 1.05, 1.18), 2), IF(ROUND((J11*1.5) * IF(J11*1.5 <= 2500, 1.05, 1.18), 2) < 2500, 25, 50) )=420, 425, CEILING( ROUND((J11*1.5) * IF(J11*1.5 <= 2500, 1.05, 1.18), 2), IF(ROUND((J11*1.5) * IF(J11*1.5 <= 2500, 1.05, 1.18), 2) < 2500, 25, 50) ) ), "" ) -> 2100 | N11: =IF(ISNUMBER(G11), CEILING(ROUND(L11*0.92,2),5), "") -> 1660 | O11: =IF(ISNUMBER(L11), IF(CEILING(ROUND(L11*1.07,2),5)=420, 425, CEILING(ROUND(L11*1.07,2),5) ), "" ) -> 1930 | P11: =IF((((G11*1.5)+50)/0.835)<2500, MROUND(((((G11*1.5)+50)/0.835)*1.05)*2,10), MROUND(((((G11*1.5)+50)/0.835)*1.18)*2,10)) -> 3790 | Q11: =IF($S$3="","", MROUND( IF($S$3="m", IF($T$3=1, Price35[[#This Row],[Mrp]]+$W$4, Price35[[#This Row],[Mrp]]+$X$4), IF($S$3="nc", IF($T$3=1, Price35[[#This Row],[Net Cash]]+$W$5, Price35[[#This Row],[Net Cash]]+$X$5), IF($S$3="npc", IF($T$3=1, Price35[[#This Row],[Net Price Credit]]+$W$6, Price35[[#This Row],[Net Price Credit]]+$X$6), IF($S$3="w", IF($T$3=1, Price35[[#This Row],[Wsp]]+$W$6, Price35[[#This Row],[Wsp]]+$X$6), "")))), 10)) -> 2170
A12: 2026 | B12: 160 | C12: shawl | D12: Fine Wool | F12: solo Plain 40*80 shawl weight 225 gm | G12: 630 | I12: 60 | J12: =IF(SUMIF(G12:I12,"<>")=0,"",SUM(G12:I12)) -> 690 | K12: =IF(ISNUMBER(L12), IF(CEILING(ROUND(L12*0.95,2),5)=420, 425, CEILING(ROUND(L12*0.95,2),5) ), "" ) -> 890 | L12: =IF(ISNUMBER(J12), IF(CEILING(ROUND(J12*1.35,2),5)=420, 425, CEILING(ROUND(J12*1.35,2),5) ), "" ) -> 935 | M12: =IF(AND(ISNUMBER(J12),ISNUMBER(G12)), IF( CEILING( ROUND((J12*1.5) * IF(J12*1.5 <= 2500, 1.05, 1.18), 2), IF(ROUND((J12*1.5) * IF(J12*1.5 <= 2500, 1.05, 1.18), 2) < 2500, 25, 50) )=420, 425, CEILING( ROUND((J12*1.5) * IF(J12*1.5 <= 2500, 1.05, 1.18), 2), IF(ROUND((J12*1.5) * IF(J12*1.5 <= 2500, 1.05, 1.18), 2) < 2500, 25, 50) ) ), "" ) -> 1100 | N12: =IF(ISNUMBER(G12), CEILING(ROUND(L12*0.92,2),5), "") -> 865 | O12: =IF(ISNUMBER(L12), IF(CEILING(ROUND(L12*1.07,2),5)=420, 425, CEILING(ROUND(L12*1.07,2),5) ), "" ) -> 1005 | P12: =IF((((G12*1.5)+50)/0.835)<2500, MROUND(((((G12*1.5)+50)/0.835)*1.05)*2,10), MROUND(((((G12*1.5)+50)/0.835)*1.18)*2,10)) -> 2500 | Q12: =IF($S$3="","", MROUND( IF($S$3="m", IF($T$3=1, Price35[[#This Row],[Mrp]]+$W$4, Price35[[#This Row],[Mrp]]+$X$4), IF($S$3="nc", IF($T$3=1, Price35[[#This Row],[Net Cash]]+$W$5, Price35[[#This Row],[Net Cash]]+$X$5), IF($S$3="npc", IF($T$3=1, Price35[[#This Row],[Net Price Credit]]+$W$6, Price35[[#This Row],[Net Price Credit]]+$X$6), IF($S$3="w", IF($T$3=1, Price35[[#This Row],[Wsp]]+$W$6, Price35[[#This Row],[Wsp]]+$X$6), "")))), 10)) -> 1170
A13: 2026 | B13: 161 | C13: shawl | D13: Fine Wool | E13: ankur | F13: 2/90 fine wool weight 180 gm | G13: 650 | I13: 60 | J13: =IF(SUMIF(G13:I13,"<>")=0,"",SUM(G13:I13)) -> 710 | K13: =IF(ISNUMBER(L13), IF(CEILING(ROUND(L13*0.95,2),5)=420, 425, CEILING(ROUND(L13*0.95,2),5) ), "" ) -> 915 | L13: =IF(ISNUMBER(J13), IF(CEILING(ROUND(J13*1.35,2),5)=420, 425, CEILING(ROUND(J13*1.35,2),5) ), "" ) -> 960 | M13: =IF(AND(ISNUMBER(J13),ISNUMBER(G13)), IF( CEILING( ROUND((J13*1.5) * IF(J13*1.5 <= 2500, 1.05, 1.18), 2), IF(ROUND((J13*1.5) * IF(J13*1.5 <= 2500, 1.05, 1.18), 2) < 2500, 25, 50) )=420, 425, CEILING( ROUND((J13*1.5) * IF(J13*1.5 <= 2500, 1.05, 1.18), 2), IF(ROUND((J13*1.5) * IF(J13*1.5 <= 2500, 1.05, 1.18), 2) < 2500, 25, 50) ) ), "" ) -> 1125 | N13: =IF(ISNUMBER(G13), CEILING(ROUND(L13*0.92,2),5), "") -> 885 | O13: =IF(ISNUMBER(L13), IF(CEILING(ROUND(L13*1.07,2),5)=420, 425, CEILING(ROUND(L13*1.07,2),5) ), "" ) -> 1030 | P13: =IF((((G13*1.5)+50)/0.835)<2500, MROUND(((((G13*1.5)+50)/0.835)*1.05)*2,10), MROUND(((((G13*1.5)+50)/0.835)*1.18)*2,10)) -> 2580 | Q13: =IF($S$3="","", MROUND( IF($S$3="m", IF($T$3=1, Price35[[#This Row],[Mrp]]+$W$4, Price35[[#This Row],[Mrp]]+$X$4), IF($S$3="nc", IF($T$3=1, Price35[[#This Row],[Net Cash]]+$W$5, Price35[[#This Row],[Net Cash]]+$X$5), IF($S$3="npc", IF($T$3=1, Price35[[#This Row],[Net Price Credit]]+$W$6, Price35[[#This Row],[Net Price Credit]]+$X$6), IF($S$3="w", IF($T$3=1, Price35[[#This Row],[Wsp]]+$W$6, Price35[[#This Row],[Wsp]]+$X$6), "")))), 10)) -> 1200
A14: 2026 | B14: 170 | C14: Lohi | D14: Fine Wool | F14: toosha gents plain 350 gm | G14: 980 | H14: 170 | I14: 60 | J14: =IF(SUMIF(G14:I14,"<>")=0,"",SUM(G14:I14)) -> 1210 | K14: =IF(ISNUMBER(L14), IF(CEILING(ROUND(L14*0.95,2),5)=420, 425, CEILING(ROUND(L14*0.95,2),5) ), "" ) -> 1555 | L14: =IF(ISNUMBER(J14), IF(CEILING(ROUND(J14*1.35,2),5)=420, 425, CEILING(ROUND(J14*1.35,2),5) ), "" ) -> 1635 | M14: =IF(AND(ISNUMBER(J14),ISNUMBER(G14)), IF( CEILING( ROUND((J14*1.5) * IF(J14*1.5 <= 2500, 1.05, 1.18), 2), IF(ROUND((J14*1.5) * IF(J14*1.5 <= 2500, 1.05, 1.18), 2) < 2500, 25, 50) )=420, 425, CEILING( ROUND((J14*1.5) * IF(J14*1.5 <= 2500, 1.05, 1.18), 2), IF(ROUND((J14*1.5) * IF(J14*1.5 <= 2500, 1.05, 1.18), 2) < 2500, 25, 50) ) ), "" ) -> 1925 | N14: =IF(ISNUMBER(G14), CEILING(ROUND(L14*0.92,2),5), "") -> 1505 | O14: =IF(ISNUMBER(L14), IF(CEILING(ROUND(L14*1.07,2),5)=420, 425, CEILING(ROUND(L14*1.07,2),5) ), "" ) -> 1750 | P14: =IF((((G14*1.5)+50)/0.835)<2500, MROUND(((((G14*1.5)+50)/0.835)*1.05)*2,10), MROUND(((((G14*1.5)+50)/0.835)*1.18)*2,10)) -> 3820 | Q14: =IF($S$3="","", MROUND( IF($S$3="m", IF($T$3=1, Price35[[#This Row],[Mrp]]+$W$4, Price35[[#This Row],[Mrp]]+$X$4), IF($S$3="nc", IF($T$3=1, Price35[[#This Row],[Net Cash]]+$W$5, Price35[[#This Row],[Net Cash]]+$X$5), IF($S$3="npc", IF($T$3=1, Price35[[#This Row],[Net Price Credit]]+$W$6, Price35[[#This Row],[Net Price Credit]]+$X$6), IF($S$3="w", IF($T$3=1, Price35[[#This Row],[Wsp]]+$W$6, Price35[[#This Row],[Wsp]]+$X$6), "")))), 10)) -> 2000
B15: 193 | C15: Lohi | D15: Fine Wool | E15: gaurav | F15: 120 count fine wool lohi | G15: 2500 | I15: 25 | J15: =IF(SUMIF(G15:I15,"<>")=0,"",SUM(G15:I15)) -> 2525 | K15: =IF(ISNUMBER(L15), IF(CEILING(ROUND(L15*0.95,2),5)=420, 425, CEILING(ROUND(L15*0.95,2),5) ), "" ) -> 3240 | L15: =IF(ISNUMBER(J15), IF(CEILING(ROUND(J15*1.35,2),5)=420, 425, CEILING(ROUND(J15*1.35,2),5) ), "" ) -> 3410 | M15: =IF(AND(ISNUMBER(J15),ISNUMBER(G15)), IF( CEILING( ROUND((J15*1.5) * IF(J15*1.5 <= 2500, 1.05, 1.18), 2), IF(ROUND((J15*1.5) * IF(J15*1.5 <= 2500, 1.05, 1.18), 2) < 2500, 25, 50) )=420, 425, CEILING( ROUND((J15*1.5) * IF(J15*1.5 <= 2500, 1.05, 1.18), 2), IF(ROUND((J15*1.5) * IF(J15*1.5 <= 2500, 1.05, 1.18), 2) < 2500, 25, 50) ) ), "" ) -> 4500 | N15: =IF(ISNUMBER(G15), CEILING(ROUND(L15*0.92,2),5), "") -> 3140 | O15: =IF(ISNUMBER(L15), IF(CEILING(ROUND(L15*1.07,2),5)=420, 425, CEILING(ROUND(L15*1.07,2),5) ), "" ) -> 3650 | P15: =IF((((G15*1.5)+50)/0.835)<2500, MROUND(((((G15*1.5)+50)/0.835)*1.05)*2,10), MROUND(((((G15*1.5)+50)/0.835)*1.18)*2,10)) -> 10740 | Q15: =IF($S$3="","", MROUND( IF($S$3="m", IF($T$3=1, Price35[[#This Row],[Mrp]]+$W$4, Price35[[#This Row],[Mrp]]+$X$4), IF($S$3="nc", IF($T$3=1, Price35[[#This Row],[Net Cash]]+$W$5, Price35[[#This Row],[Net Cash]]+$X$5), IF($S$3="npc", IF($T$3=1, Price35[[#This Row],[Net Price Credit]]+$W$6, Price35[[#This Row],[Net Price Credit]]+$X$6), IF($S$3="w", IF($T$3=1, Price35[[#This Row],[Wsp]]+$W$6, Price35[[#This Row],[Wsp]]+$X$6), "")))), 10)) -> 4570
B16: 710 | C16: Lohi | D16: wool | F16: 45*90 gents | G16: 340 | I16: 50 | J16: =IF(SUMIF(G16:I16,"<>")=0,"",SUM(G16:I16)) -> 390 | K16: =IF(ISNUMBER(L16), IF(CEILING(ROUND(L16*0.95,2),5)=420, 425, CEILING(ROUND(L16*0.95,2),5) ), "" ) -> 505 | L16: =IF(ISNUMBER(J16), IF(CEILING(ROUND(J16*1.35,2),5)=420, 425, CEILING(ROUND(J16*1.35,2),5) ), "" ) -> 530 | M16: =IF(AND(ISNUMBER(J16),ISNUMBER(G16)), IF( CEILING( ROUND((J16*1.5) * IF(J16*1.5 <= 2500, 1.05, 1.18), 2), IF(ROUND((J16*1.5) * IF(J16*1.5 <= 2500, 1.05, 1.18), 2) < 2500, 25, 50) )=420, 425, CEILING( ROUND((J16*1.5) * IF(J16*1.5 <= 2500, 1.05, 1.18), 2), IF(ROUND((J16*1.5) * IF(J16*1.5 <= 2500, 1.05, 1.18), 2) < 2500, 25, 50) ) ), "" ) -> 625 | N16: =IF(ISNUMBER(G16), CEILING(ROUND(L16*0.92,2),5), "") -> 490 | O16: =IF(ISNUMBER(L16), IF(CEILING(ROUND(L16*1.07,2),5)=420, 425, CEILING(ROUND(L16*1.07,2),5) ), "" ) -> 570 | P16: =IF((((G16*1.5)+50)/0.835)<2500, MROUND(((((G16*1.5)+50)/0.835)*1.05)*2,10), MROUND(((((G16*1.5)+50)/0.835)*1.18)*2,10)) -> 1410 | Q16: =IF($S$3="","", MROUND( IF($S$3="m", IF($T$3=1, Price35[[#This Row],[Mrp]]+$W$4, Price35[[#This Row],[Mrp]]+$X$4), IF($S$3="nc", IF($T$3=1, Price35[[#This Row],[Net Cash]]+$W$5, Price35[[#This Row],[Net Cash]]+$X$5), IF($S$3="npc", IF($T$3=1, Price35[[#This Row],[Net Price Credit]]+$W$6, Price35[[#This Row],[Net Price Credit]]+$X$6), IF($S$3="w", IF($T$3=1, Price35[[#This Row],[Wsp]]+$W$6, Price35[[#This Row],[Wsp]]+$X$6), "")))), 10)) -> 700
A17: 2026 | B17: 910 | C17: Lohi | D17: wool | F17: malida | G17: 500 | I17: 100 | J17: =IF(SUMIF(G17:I17,"<>")=0,"",SUM(G17:I17)) -> 600 | K17: =IF(ISNUMBER(L17), IF(CEILING(ROUND(L17*0.95,2),5)=420, 425, CEILING(ROUND(L17*0.95,2),5) ), "" ) -> 770 | L17: =IF(ISNUMBER(J17), IF(CEILING(ROUND(J17*1.35,2),5)=420, 425, CEILING(ROUND(J17*1.35,2),5) ), "" ) -> 810 | M17: =IF(AND(ISNUMBER(J17),ISNUMBER(G17)), IF( CEILING( ROUND((J17*1.5) * IF(J17*1.5 <= 2500, 1.05, 1.18), 2), IF(ROUND((J17*1.5) * IF(J17*1.5 <= 2500, 1.05, 1.18), 2) < 2500, 25, 50) )=420, 425, CEILING( ROUND((J17*1.5) * IF(J17*1.5 <= 2500, 1.05, 1.18), 2), IF(ROUND((J17*1.5) * IF(J17*1.5 <= 2500, 1.05, 1.18), 2) < 2500, 25, 50) ) ), "" ) -> 950 | N17: =IF(ISNUMBER(G17), CEILING(ROUND(L17*0.92,2),5), "") -> 750 | O17: =IF(ISNUMBER(L17), IF(CEILING(ROUND(L17*1.07,2),5)=420, 425, CEILING(ROUND(L17*1.07,2),5) ), "" ) -> 870 | P17: =IF((((G17*1.5)+50)/0.835)<2500, MROUND(((((G17*1.5)+50)/0.835)*1.05)*2,10), MROUND(((((G17*1.5)+50)/0.835)*1.18)*2,10)) -> 2010 | Q17: =IF($S$3="","", MROUND( IF($S$3="m", IF($T$3=1, Price35[[#This Row],[Mrp]]+$W$4, Price35[[#This Row],[Mrp]]+$X$4), IF($S$3="nc", IF($T$3=1, Price35[[#This Row],[Net Cash]]+$W$5, Price35[[#This Row],[Net Cash]]+$X$5), IF($S$3="npc", IF($T$3=1, Price35[[#This Row],[Net Price Credit]]+$W$6, Price35[[#This Row],[Net Price Credit]]+$X$6), IF($S$3="w", IF($T$3=1, Price35[[#This Row],[Wsp]]+$W$6, Price35[[#This Row],[Wsp]]+$X$6), "")))), 10)) -> 1020
A18: 2026 | B18: 1000 | C18: Lohi | D18: wool | F18: ramayan lohi jay dee 80 x 20 | G18: 693 | I18: 15 | J18: =IF(SUMIF(G18:I18,"<>")=0,"",SUM(G18:I18)) -> 708 | K18: =IF(ISNUMBER(L18), IF(CEILING(ROUND(L18*0.95,2),5)=420, 425, CEILING(ROUND(L18*0.95,2),5) ), "" ) -> 915 | L18: =IF(ISNUMBER(J18), IF(CEILING(ROUND(J18*1.35,2),5)=420, 425, CEILING(ROUND(J18*1.35,2),5) ), "" ) -> 960 | M18: =IF(AND(ISNUMBER(J18),ISNUMBER(G18)), IF( CEILING( ROUND((J18*1.5) * IF(J18*1.5 <= 2500, 1.05, 1.18), 2), IF(ROUND((J18*1.5) * IF(J18*1.5 <= 2500, 1.05, 1.18), 2) < 2500, 25, 50) )=420, 425, CEILING( ROUND((J18*1.5) * IF(J18*1.5 <= 2500, 1.05, 1.18), 2), IF(ROUND((J18*1.5) * IF(J18*1.5 <= 2500, 1.05, 1.18), 2) < 2500, 25, 50) ) ), "" ) -> 1125 | N18: =IF(ISNUMBER(G18), CEILING(ROUND(L18*0.92,2),5), "") -> 885 | O18: =IF(ISNUMBER(L18), IF(CEILING(ROUND(L18*1.07,2),5)=420, 425, CEILING(ROUND(L18*1.07,2),5) ), "" ) -> 1030 | P18: =IF((((G18*1.5)+50)/0.835)<2500, MROUND(((((G18*1.5)+50)/0.835)*1.05)*2,10), MROUND(((((G18*1.5)+50)/0.835)*1.18)*2,10)) -> 2740 | Q18: =IF($S$3="","", MROUND( IF($S$3="m", IF($T$3=1, Price35[[#This Row],[Mrp]]+$W$4, Price35[[#This Row],[Mrp]]+$X$4), IF($S$3="nc", IF($T$3=1, Price35[[#This Row],[Net Cash]]+$W$5, Price35[[#This Row],[Net Cash]]+$X$5), IF($S$3="npc", IF($T$3=1, Price35[[#This Row],[Net Price Credit]]+$W$6, Price35[[#This Row],[Net Price Credit]]+$X$6), IF($S$3="w", IF($T$3=1, Price35[[#This Row],[Wsp]]+$W$6, Price35[[#This Row],[Wsp]]+$X$6), "")))), 10)) -> 1200
B19: 1010 | C19: Lohi | D19: wool | F19: malida 10 no. | G19: 480 | I19: 80 | J19: =IF(SUMIF(G19:I19,"<>")=0,"",SUM(G19:I19)) -> 560 | K19: =IF(ISNUMBER(L19), IF(CEILING(ROUND(L19*0.95,2),5)=420, 425, CEILING(ROUND(L19*0.95,2),5) ), "" ) -> 725 | L19: =IF(ISNUMBER(J19), IF(CEILING(ROUND(J19*1.35,2),5)=420, 425, CEILING(ROUND(J19*1.35,2),5) ), "" ) -> 760 | M19: =IF(AND(ISNUMBER(J19),ISNUMBER(G19)), IF( CEILING( ROUND((J19*1.5) * IF(J19*1.5 <= 2500, 1.05, 1.18), 2), IF(ROUND((J19*1.5) * IF(J19*1.5 <= 2500, 1.05, 1.18), 2) < 2500, 25, 50) )=420, 425, CEILING( ROUND((J19*1.5) * IF(J19*1.5 <= 2500, 1.05, 1.18), 2), IF(ROUND((J19*1.5) * IF(J19*1.5 <= 2500, 1.05, 1.18), 2) < 2500, 25, 50) ) ), "" ) -> 900 | N19: =IF(ISNUMBER(G19), CEILING(ROUND(L19*0.92,2),5), "") -> 700 | O19: =IF(ISNUMBER(L19), IF(CEILING(ROUND(L19*1.07,2),5)=420, 425, CEILING(ROUND(L19*1.07,2),5) ), "" ) -> 815 | P19: =IF((((G19*1.5)+50)/0.835)<2500, MROUND(((((G19*1.5)+50)/0.835)*1.05)*2,10), MROUND(((((G19*1.5)+50)/0.835)*1.18)*2,10)) -> 1940 | Q19: =IF($S$3="","", MROUND( IF($S$3="m", IF($T$3=1, Price35[[#This Row],[Mrp]]+$W$4, Price35[[#This Row],[Mrp]]+$X$4), IF($S$3="nc", IF($T$3=1, Price35[[#This Row],[Net Cash]]+$W$5, Price35[[#This Row],[Net Cash]]+$X$5), IF($S$3="npc", IF($T$3=1, Price35[[#This Row],[Net Price Credit]]+$W$6, Price35[[#This Row],[Net Price Credit]]+$X$6), IF($S$3="w", IF($T$3=1, Price35[[#This Row],[Wsp]]+$W$6, Price35[[#This Row],[Wsp]]+$X$6), "")))), 10)) -> 970
A20: 2026 | B20: 1651 | C20: Lohi | D20: wool | E20: international | F20: malida 1651 no.pure wool 450 gm | G20: 881 | I20: 25 | J20: =IF(SUMIF(G20:I20,"<>")=0,"",SUM(G20:I20)) -> 906 | K20: =IF(ISNUMBER(L20), IF(CEILING(ROUND(L20*0.95,2),5)=420, 425, CEILING(ROUND(L20*0.95,2),5) ), "" ) -> 1165 | L20: =IF(ISNUMBER(J20), IF(CEILING(ROUND(J20*1.35,2),5)=420, 425, CEILING(ROUND(J20*1.35,2),5) ), "" ) -> 1225 | M20: =IF(AND(ISNUMBER(J20),ISNUMBER(G20)), IF( CEILING( ROUND((J20*1.5) * IF(J20*1.5 <= 2500, 1.05, 1.18), 2), IF(ROUND((J20*1.5) * IF(J20*1.5 <= 2500, 1.05, 1.18), 2) < 2500, 25, 50) )=420, 425, CEILING( ROUND((J20*1.5) * IF(J20*1.5 <= 2500, 1.05, 1.18), 2), IF(ROUND((J20*1.5) * IF(J20*1.5 <= 2500, 1.05, 1.18), 2) < 2500, 25, 50) ) ), "" ) -> 1450 | N20: =IF(ISNUMBER(G20), CEILING(ROUND(L20*0.92,2),5), "") -> 1130 | O20: =IF(ISNUMBER(L20), IF(CEILING(ROUND(L20*1.07,2),5)=420, 425, CEILING(ROUND(L20*1.07,2),5) ), "" ) -> 1315 | P20: =IF((((G20*1.5)+50)/0.835)<2500, MROUND(((((G20*1.5)+50)/0.835)*1.05)*2,10), MROUND(((((G20*1.5)+50)/0.835)*1.18)*2,10)) -> 3450 | Q20: =IF($S$3="","", MROUND( IF($S$3="m", IF($T$3=1, Price35[[#This Row],[Mrp]]+$W$4, Price35[[#This Row],[Mrp]]+$X$4), IF($S$3="nc", IF($T$3=1, Price35[[#This Row],[Net Cash]]+$W$5, Price35[[#This Row],[Net Cash]]+$X$5), IF($S$3="npc", IF($T$3=1, Price35[[#This Row],[Net Price Credit]]+$W$6, Price35[[#This Row],[Net Price Credit]]+$X$6), IF($S$3="w", IF($T$3=1, Price35[[#This Row],[Wsp]]+$W$6, Price35[[#This Row],[Wsp]]+$X$6), "")))), 10)) -> 1520
A21: 2026 | B21: 2400 | C21: Lohi | D21: wool | F21: lohi govinda 80 x 20 jay dee | G21: 936 | I21: 15 | J21: =IF(SUMIF(G21:I21,"<>")=0,"",SUM(G21:I21)) -> 951 | K21: =IF(ISNUMBER(L21), IF(CEILING(ROUND(L21*0.95,2),5)=420, 425, CEILING(ROUND(L21*0.95,2),5) ), "" ) -> 1225 | L21: =IF(ISNUMBER(J21), IF(CEILING(ROUND(J21*1.35,2),5)=420, 425, CEILING(ROUND(J21*1.35,2),5) ), "" ) -> 1285 | M21: =IF(AND(ISNUMBER(J21),ISNUMBER(G21)), IF( CEILING( ROUND((J21*1.5) * IF(J21*1.5 <= 2500, 1.05, 1.18), 2), IF(ROUND((J21*1.5) * IF(J21*1.5 <= 2500, 1.05, 1.18), 2) < 2500, 25, 50) )=420, 425, CEILING( ROUND((J21*1.5) * IF(J21*1.5 <= 2500, 1.05, 1.18), 2), IF(ROUND((J21*1.5) * IF(J21*1.5 <= 2500, 1.05, 1.18), 2) < 2500, 25, 50) ) ), "" ) -> 1500 | N21: =IF(ISNUMBER(G21), CEILING(ROUND(L21*0.92,2),5), "") -> 1185 | O21: =IF(ISNUMBER(L21), IF(CEILING(ROUND(L21*1.07,2),5)=420, 425, CEILING(ROUND(L21*1.07,2),5) ), "" ) -> 1375 | P21: =IF((((G21*1.5)+50)/0.835)<2500, MROUND(((((G21*1.5)+50)/0.835)*1.05)*2,10), MROUND(((((G21*1.5)+50)/0.835)*1.18)*2,10)) -> 3660 | Q21: =IF($S$3="","", MROUND( IF($S$3="m", IF($T$3=1, Price35[[#This Row],[Mrp]]+$W$4, Price35[[#This Row],[Mrp]]+$X$4), IF($S$3="nc", IF($T$3=1, Price35[[#This Row],[Net Cash]]+$W$5, Price35[[#This Row],[Net Cash]]+$X$5), IF($S$3="npc", IF($T$3=1, Price35[[#This Row],[Net Price Credit]]+$W$6, Price35[[#This Row],[Net Price Credit]]+$X$6), IF($S$3="w", IF($T$3=1, Price35[[#This Row],[Wsp]]+$W$6, Price35[[#This Row],[Wsp]]+$X$6), "")))), 10)) -> 1570
A22: 2026 | B22: 2451 | C22: Lohi | D22: wool | E22: international | F22: malida 2451 no. pure wool 650gm | G22: 1303 | I22: 25 | J22: =IF(SUMIF(G22:I22,"<>")=0,"",SUM(G22:I22)) -> 1328 | K22: =IF(ISNUMBER(L22), IF(CEILING(ROUND(L22*0.95,2),5)=420, 425, CEILING(ROUND(L22*0.95,2),5) ), "" ) -> 1710 | L22: =IF(ISNUMBER(J22), IF(CEILING(ROUND(J22*1.35,2),5)=420, 425, CEILING(ROUND(J22*1.35,2),5) ), "" ) -> 1795 | M22: =IF(AND(ISNUMBER(J22),ISNUMBER(G22)), IF( CEILING( ROUND((J22*1.5) * IF(J22*1.5 <= 2500, 1.05, 1.18), 2), IF(ROUND((J22*1.5) * IF(J22*1.5 <= 2500, 1.05, 1.18), 2) < 2500, 25, 50) )=420, 425, CEILING( ROUND((J22*1.5) * IF(J22*1.5 <= 2500, 1.05, 1.18), 2), IF(ROUND((J22*1.5) * IF(J22*1.5 <= 2500, 1.05, 1.18), 2) < 2500, 25, 50) ) ), "" ) -> 2100 | N22: =IF(ISNUMBER(G22), CEILING(ROUND(L22*0.92,2),5), "") -> 1655 | O22: =IF(ISNUMBER(L22), IF(CEILING(ROUND(L22*1.07,2),5)=420, 425, CEILING(ROUND(L22*1.07,2),5) ), "" ) -> 1925 | P22: =IF((((G22*1.5)+50)/0.835)<2500, MROUND(((((G22*1.5)+50)/0.835)*1.05)*2,10), MROUND(((((G22*1.5)+50)/0.835)*1.18)*2,10)) -> 5040 | Q22: =IF($S$3="","", MROUND( IF($S$3="m", IF($T$3=1, Price35[[#This Row],[Mrp]]+$W$4, Price35[[#This Row],[Mrp]]+$X$4), IF($S$3="nc", IF($T$3=1, Price35[[#This Row],[Net Cash]]+$W$5, Price35[[#This Row],[Net Cash]]+$X$5), IF($S$3="npc", IF($T$3=1, Price35[[#This Row],[Net Price Credit]]+$W$6, Price35[[#This Row],[Net Price Credit]]+$X$6), IF($S$3="w", IF($T$3=1, Price35[[#This Row],[Wsp]]+$W$6, Price35[[#This Row],[Wsp]]+$X$6), "")))), 10)) -> 2170
A23: 2026 | B23: 142 | C23: shawl | D23: Polywool | E23: MM enterprises | F23: shahtoosh 2/72 polywool | G23: 370 | I23: 265 | J23: =IF(SUMIF(G23:I23,"<>")=0,"",SUM(G23:I23)) -> 635 | K23: =IF(ISNUMBER(L23), IF(CEILING(ROUND(L23*0.95,2),5)=420, 425, CEILING(ROUND(L23*0.95,2),5) ), "" ) -> 820 | L23: =IF(ISNUMBER(J23), IF(CEILING(ROUND(J23*1.35,2),5)=420, 425, CEILING(ROUND(J23*1.35,2),5) ), "" ) -> 860 | M23: =IF(AND(ISNUMBER(J23),ISNUMBER(G23)), IF( CEILING( ROUND((J23*1.5) * IF(J23*1.5 <= 2500, 1.05, 1.18), 2), IF(ROUND((J23*1.5) * IF(J23*1.5 <= 2500, 1.05, 1.18), 2) < 2500, 25, 50) )=420, 425, CEILING( ROUND((J23*1.5) * IF(J23*1.5 <= 2500, 1.05, 1.18), 2), IF(ROUND((J23*1.5) * IF(J23*1.5 <= 2500, 1.05, 1.18), 2) < 2500, 25, 50) ) ), "" ) -> 1025 | N23: =IF(ISNUMBER(G23), CEILING(ROUND(L23*0.92,2),5), "") -> 795 | O23: =IF(ISNUMBER(L23), IF(CEILING(ROUND(L23*1.07,2),5)=420, 425, CEILING(ROUND(L23*1.07,2),5) ), "" ) -> 925 | P23: =IF((((G23*1.5)+50)/0.835)<2500, MROUND(((((G23*1.5)+50)/0.835)*1.05)*2,10), MROUND(((((G23*1.5)+50)/0.835)*1.18)*2,10)) -> 1520 | Q23: =IF($S$3="","", MROUND( IF($S$3="m", IF($T$3=1, Price35[[#This Row],[Mrp]]+$W$4, Price35[[#This Row],[Mrp]]+$X$4), IF($S$3="nc", IF($T$3=1, Price35[[#This Row],[Net Cash]]+$W$5, Price35[[#This Row],[Net Cash]]+$X$5), IF($S$3="npc", IF($T$3=1, Price35[[#This Row],[Net Price Credit]]+$W$6, Price35[[#This Row],[Net Price Credit]]+$X$6), IF($S$3="w", IF($T$3=1, Price35[[#This Row],[Wsp]]+$W$6, Price35[[#This Row],[Wsp]]+$X$6), "")))), 10)) -> 1100
A24: 2026 | B24: 143 | C24: shawl | D24: Polywool | E24: MM enterprises | F24: shahtoosh 2/72 polywool 50*100 | G24: 500 | I24: 325 | J24: =IF(SUMIF(G24:I24,"<>")=0,"",SUM(G24:I24)) -> 825 | K24: =IF(ISNUMBER(L24), IF(CEILING(ROUND(L24*0.95,2),5)=420, 425, CEILING(ROUND(L24*0.95,2),5) ), "" ) -> 1060 | L24: =IF(ISNUMBER(J24), IF(CEILING(ROUND(J24*1.35,2),5)=420, 425, CEILING(ROUND(J24*1.35,2),5) ), "" ) -> 1115 | M24: =IF(AND(ISNUMBER(J24),ISNUMBER(G24)), IF( CEILING( ROUND((J24*1.5) * IF(J24*1.5 <= 2500, 1.05, 1.18), 2), IF(ROUND((J24*1.5) * IF(J24*1.5 <= 2500, 1.05, 1.18), 2) < 2500, 25, 50) )=420, 425, CEILING( ROUND((J24*1.5) * IF(J24*1.5 <= 2500, 1.05, 1.18), 2), IF(ROUND((J24*1.5) * IF(J24*1.5 <= 2500, 1.05, 1.18), 2) < 2500, 25, 50) ) ), "" ) -> 1300 | N24: =IF(ISNUMBER(G24), CEILING(ROUND(L24*0.92,2),5), "") -> 1030 | O24: =IF(ISNUMBER(L24), IF(CEILING(ROUND(L24*1.07,2),5)=420, 425, CEILING(ROUND(L24*1.07,2),5) ), "" ) -> 1195 | P24: =IF((((G24*1.5)+50)/0.835)<2500, MROUND(((((G24*1.5)+50)/0.835)*1.05)*2,10), MROUND(((((G24*1.5)+50)/0.835)*1.18)*2,10)) -> 2010 | Q24: =IF($S$3="","", MROUND( IF($S$3="m", IF($T$3=1, Price35[[#This Row],[Mrp]]+$W$4, Price35[[#This Row],[Mrp]]+$X$4), IF($S$3="nc", IF($T$3=1, Price35[[#This Row],[Net Cash]]+$W$5, Price35[[#This Row],[Net Cash]]+$X$5), IF($S$3="npc", IF($T$3=1, Price35[[#This Row],[Net Price Credit]]+$W$6, Price35[[#This Row],[Net Price Credit]]+$X$6), IF($S$3="w", IF($T$3=1, Price35[[#This Row],[Wsp]]+$W$6, Price35[[#This Row],[Wsp]]+$X$6), "")))), 10)) -> 1370
B25: 948 | C25: shawl | D25: Kashmiri | F25: hashia | G25: 390 | I25: 215 | J25: =IF(SUMIF(G25:I25,"<>")=0,"",SUM(G25:I25)) -> 605 | K25: =IF(ISNUMBER(L25), IF(CEILING(ROUND(L25*0.95,2),5)=420, 425, CEILING(ROUND(L25*0.95,2),5) ), "" ) -> 780 | L25: =IF(ISNUMBER(J25), IF(CEILING(ROUND(J25*1.35,2),5)=420, 425, CEILING(ROUND(J25*1.35,2),5) ), "" ) -> 820 | M25: =IF(AND(ISNUMBER(J25),ISNUMBER(G25)), IF( CEILING( ROUND((J25*1.5) * IF(J25*1.5 <= 2500, 1.05, 1.18), 2), IF(ROUND((J25*1.5) * IF(J25*1.5 <= 2500, 1.05, 1.18), 2) < 2500, 25, 50) )=420, 425, CEILING( ROUND((J25*1.5) * IF(J25*1.5 <= 2500, 1.05, 1.18), 2), IF(ROUND((J25*1.5) * IF(J25*1.5 <= 2500, 1.05, 1.18), 2) < 2500, 25, 50) ) ), "" ) -> 975 | N25: =IF(ISNUMBER(G25), CEILING(ROUND(L25*0.92,2),5), "") -> 755 | O25: =IF(ISNUMBER(L25), IF(CEILING(ROUND(L25*1.07,2),5)=420, 425, CEILING(ROUND(L25*1.07,2),5) ), "" ) -> 880 | P25: =IF((((G25*1.5)+50)/0.835)<2500, MROUND(((((G25*1.5)+50)/0.835)*1.05)*2,10), MROUND(((((G25*1.5)+50)/0.835)*1.18)*2,10)) -> 1600 | Q25: =IF($S$3="","", MROUND( IF($S$3="m", IF($T$3=1, Price35[[#This Row],[Mrp]]+$W$4, Price35[[#This Row],[Mrp]]+$X$4), IF($S$3="nc", IF($T$3=1, Price35[[#This Row],[Net Cash]]+$W$5, Price35[[#This Row],[Net Cash]]+$X$5), IF($S$3="npc", IF($T$3=1, Price35[[#This Row],[Net Price Credit]]+$W$6, Price35[[#This Row],[Net Price Credit]]+$X$6), IF($S$3="w", IF($T$3=1, Price35[[#This Row],[Wsp]]+$W$6, Price35[[#This Row],[Wsp]]+$X$6), "")))), 10)) -> 1050
B26: 949 | C26: shawl | D26: Kashmiri | F26: hashia 14 no. | G26: 460 | I26: 215 | J26: =IF(SUMIF(G26:I26,"<>")=0,"",SUM(G26:I26)) -> 675 | K26: =IF(ISNUMBER(L26), IF(CEILING(ROUND(L26*0.95,2),5)=420, 425, CEILING(ROUND(L26*0.95,2),5) ), "" ) -> 870 | L26: =IF(ISNUMBER(J26), IF(CEILING(ROUND(J26*1.35,2),5)=420, 425, CEILING(ROUND(J26*1.35,2),5) ), "" ) -> 915 | M26: =IF(AND(ISNUMBER(J26),ISNUMBER(G26)), IF( CEILING( ROUND((J26*1.5) * IF(J26*1.5 <= 2500, 1.05, 1.18), 2), IF(ROUND((J26*1.5) * IF(J26*1.5 <= 2500, 1.05, 1.18), 2) < 2500, 25, 50) )=420, 425, CEILING( ROUND((J26*1.5) * IF(J26*1.5 <= 2500, 1.05, 1.18), 2), IF(ROUND((J26*1.5) * IF(J26*1.5 <= 2500, 1.05, 1.18), 2) < 2500, 25, 50) ) ), "" ) -> 1075 | N26: =IF(ISNUMBER(G26), CEILING(ROUND(L26*0.92,2),5), "") -> 845 | O26: =IF(ISNUMBER(L26), IF(CEILING(ROUND(L26*1.07,2),5)=420, 425, CEILING(ROUND(L26*1.07,2),5) ), "" ) -> 980 | P26: =IF((((G26*1.5)+50)/0.835)<2500, MROUND(((((G26*1.5)+50)/0.835)*1.05)*2,10), MROUND(((((G26*1.5)+50)/0.835)*1.18)*2,10)) -> 1860 | Q26: =IF($S$3="","", MROUND( IF($S$3="m", IF($T$3=1, Price35[[#This Row],[Mrp]]+$W$4, Price35[[#This Row],[Mrp]]+$X$4), IF($S$3="nc", IF($T$3=1, Price35[[#This Row],[Net Cash]]+$W$5, Price35[[#This Row],[Net Cash]]+$X$5), IF($S$3="npc", IF($T$3=1, Price35[[#This Row],[Net Price Credit]]+$W$6, Price35[[#This Row],[Net Price Credit]]+$X$6), IF($S$3="w", IF($T$3=1, Price35[[#This Row],[Wsp]]+$W$6, Price35[[#This Row],[Wsp]]+$X$6), "")))), 10)) -> 1150
B27: 951 | C27: shawl | D27: Kashmiri | F27: mini neem dour multihead 13 no. | G27: 390 | I27: 300 | J27: =IF(SUMIF(G27:I27,"<>")=0,"",SUM(G27:I27)) -> 690 | K27: =IF(ISNUMBER(L27), IF(CEILING(ROUND(L27*0.95,2),5)=420, 425, CEILING(ROUND(L27*0.95,2),5) ), "" ) -> 890 | L27: =IF(ISNUMBER(J27), IF(CEILING(ROUND(J27*1.35,2),5)=420, 425, CEILING(ROUND(J27*1.35,2),5) ), "" ) -> 935 | M27: =IF(AND(ISNUMBER(J27),ISNUMBER(G27)), IF( CEILING( ROUND((J27*1.5) * IF(J27*1.5 <= 2500, 1.05, 1.18), 2), IF(ROUND((J27*1.5) * IF(J27*1.5 <= 2500, 1.05, 1.18), 2) < 2500, 25, 50) )=420, 425, CEILING( ROUND((J27*1.5) * IF(J27*1.5 <= 2500, 1.05, 1.18), 2), IF(ROUND((J27*1.5) * IF(J27*1.5 <= 2500, 1.05, 1.18), 2) < 2500, 25, 50) ) ), "" ) -> 1100 | N27: =IF(ISNUMBER(G27), CEILING(ROUND(L27*0.92,2),5), "") -> 865 | O27: =IF(ISNUMBER(L27), IF(CEILING(ROUND(L27*1.07,2),5)=420, 425, CEILING(ROUND(L27*1.07,2),5) ), "" ) -> 1005 | P27: =IF((((G27*1.5)+50)/0.835)<2500, MROUND(((((G27*1.5)+50)/0.835)*1.05)*2,10), MROUND(((((G27*1.5)+50)/0.835)*1.18)*2,10)) -> 1600 | Q27: =IF($S$3="","", MROUND( IF($S$3="m", IF($T$3=1, Price35[[#This Row],[Mrp]]+$W$4, Price35[[#This Row],[Mrp]]+$X$4), IF($S$3="nc", IF($T$3=1, Price35[[#This Row],[Net Cash]]+$W$5, Price35[[#This Row],[Net Cash]]+$X$5), IF($S$3="npc", IF($T$3=1, Price35[[#This Row],[Net Price Credit]]+$W$6, Price35[[#This Row],[Net Price Credit]]+$X$6), IF($S$3="w", IF($T$3=1, Price35[[#This Row],[Wsp]]+$W$6, Price35[[#This Row],[Wsp]]+$X$6), "")))), 10)) -> 1170
A28: 2026 | B28: 959 | C28: shawl | D28: Kashmiri | E28: sharma | F28: c.n.d multihead new | G28: 390 | I28: 265 | J28: =IF(SUMIF(G28:I28,"<>")=0,"",SUM(G28:I28)) -> 655 | K28: =IF(ISNUMBER(L28), IF(CEILING(ROUND(L28*0.95,2),5)=420, 425, CEILING(ROUND(L28*0.95,2),5) ), "" ) -> 845 | L28: =IF(ISNUMBER(J28), IF(CEILING(ROUND(J28*1.35,2),5)=420, 425, CEILING(ROUND(J28*1.35,2),5) ), "" ) -> 885 | M28: =IF(AND(ISNUMBER(J28),ISNUMBER(G28)), IF( CEILING( ROUND((J28*1.5) * IF(J28*1.5 <= 2500, 1.05, 1.18), 2), IF(ROUND((J28*1.5) * IF(J28*1.5 <= 2500, 1.05, 1.18), 2) < 2500, 25, 50) )=420, 425, CEILING( ROUND((J28*1.5) * IF(J28*1.5 <= 2500, 1.05, 1.18), 2), IF(ROUND((J28*1.5) * IF(J28*1.5 <= 2500, 1.05, 1.18), 2) < 2500, 25, 50) ) ), "" ) -> 1050 | N28: =IF(ISNUMBER(G28), CEILING(ROUND(L28*0.92,2),5), "") -> 815 | O28: =IF(ISNUMBER(L28), IF(CEILING(ROUND(L28*1.07,2),5)=420, 425, CEILING(ROUND(L28*1.07,2),5) ), "" ) -> 950 | P28: =IF((((G28*1.5)+50)/0.835)<2500, MROUND(((((G28*1.5)+50)/0.835)*1.05)*2,10), MROUND(((((G28*1.5)+50)/0.835)*1.18)*2,10)) -> 1600 | Q28: =IF($S$3="","", MROUND( IF($S$3="m", IF($T$3=1, Price35[[#This Row],[Mrp]]+$W$4, Price35[[#This Row],[Mrp]]+$X$4), IF($S$3="nc", IF($T$3=1, Price35[[#This Row],[Net Cash]]+$W$5, Price35[[#This Row],[Net Cash]]+$X$5), IF($S$3="npc", IF($T$3=1, Price35[[#This Row],[Net Price Credit]]+$W$6, Price35[[#This Row],[Net Price Credit]]+$X$6), IF($S$3="w", IF($T$3=1, Price35[[#This Row],[Wsp]]+$W$6, Price35[[#This Row],[Wsp]]+$X$6), "")))), 10)) -> 1120
B29: 960 | C29: shawl | D29: Kashmiri | F29: hashia multihead 14 no. | G29: 460 | I29: 325 | J29: =IF(SUMIF(G29:I29,"<>")=0,"",SUM(G29:I29)) -> 785 | K29: =IF(ISNUMBER(L29), IF(CEILING(ROUND(L29*0.95,2),5)=420, 425, CEILING(ROUND(L29*0.95,2),5) ), "" ) -> 1010 | L29: =IF(ISNUMBER(J29), IF(CEILING(ROUND(J29*1.35,2),5)=420, 425, CEILING(ROUND(J29*1.35,2),5) ), "" ) -> 1060 | M29: =IF(AND(ISNUMBER(J29),ISNUMBER(G29)), IF( CEILING( ROUND((J29*1.5) * IF(J29*1.5 <= 2500, 1.05, 1.18), 2), IF(ROUND((J29*1.5) * IF(J29*1.5 <= 2500, 1.05, 1.18), 2) < 2500, 25, 50) )=420, 425, CEILING( ROUND((J29*1.5) * IF(J29*1.5 <= 2500, 1.05, 1.18), 2), IF(ROUND((J29*1.5) * IF(J29*1.5 <= 2500, 1.05, 1.18), 2) < 2500, 25, 50) ) ), "" ) -> 1250 | N29: =IF(ISNUMBER(G29), CEILING(ROUND(L29*0.92,2),5), "") -> 980 | O29: =IF(ISNUMBER(L29), IF(CEILING(ROUND(L29*1.07,2),5)=420, 425, CEILING(ROUND(L29*1.07,2),5) ), "" ) -> 1135 | P29: =IF((((G29*1.5)+50)/0.835)<2500, MROUND(((((G29*1.5)+50)/0.835)*1.05)*2,10), MROUND(((((G29*1.5)+50)/0.835)*1.18)*2,10)) -> 1860 | Q29: =IF($S$3="","", MROUND( IF($S$3="m", IF($T$3=1, Price35[[#This Row],[Mrp]]+$W$4, Price35[[#This Row],[Mrp]]+$X$4), IF($S$3="nc", IF($T$3=1, Price35[[#This Row],[Net Cash]]+$W$5, Price35[[#This Row],[Net Cash]]+$X$5), IF($S$3="npc", IF($T$3=1, Price35[[#This Row],[Net Price Credit]]+$W$6, Price35[[#This Row],[Net Price Credit]]+$X$6), IF($S$3="w", IF($T$3=1, Price35[[#This Row],[Wsp]]+$W$6, Price35[[#This Row],[Wsp]]+$X$6), "")))), 10)) -> 1320
B30: 962 | C30: shawl | D30: Kashmiri | F30: variety 14 no. | G30: 460 | I30: 310 | J30: =IF(SUMIF(G30:I30,"<>")=0,"",SUM(G30:I30)) -> 770 | K30: =IF(ISNUMBER(L30), IF(CEILING(ROUND(L30*0.95,2),5)=420, 425, CEILING(ROUND(L30*0.95,2),5) ), "" ) -> 990 | L30: =IF(ISNUMBER(J30), IF(CEILING(ROUND(J30*1.35,2),5)=420, 425, CEILING(ROUND(J30*1.35,2),5) ), "" ) -> 1040 | M30: =IF(AND(ISNUMBER(J30),ISNUMBER(G30)), IF( CEILING( ROUND((J30*1.5) * IF(J30*1.5 <= 2500, 1.05, 1.18), 2), IF(ROUND((J30*1.5) * IF(J30*1.5 <= 2500, 1.05, 1.18), 2) < 2500, 25, 50) )=420, 425, CEILING( ROUND((J30*1.5) * IF(J30*1.5 <= 2500, 1.05, 1.18), 2), IF(ROUND((J30*1.5) * IF(J30*1.5 <= 2500, 1.05, 1.18), 2) < 2500, 25, 50) ) ), "" ) -> 1225 | N30: =IF(ISNUMBER(G30), CEILING(ROUND(L30*0.92,2),5), "") -> 960 | O30: =IF(ISNUMBER(L30), IF(CEILING(ROUND(L30*1.07,2),5)=420, 425, CEILING(ROUND(L30*1.07,2),5) ), "" ) -> 1115 | P30: =IF((((G30*1.5)+50)/0.835)<2500, MROUND(((((G30*1.5)+50)/0.835)*1.05)*2,10), MROUND(((((G30*1.5)+50)/0.835)*1.18)*2,10)) -> 1860 | Q30: =IF($S$3="","", MROUND( IF($S$3="m", IF($T$3=1, Price35[[#This Row],[Mrp]]+$W$4, Price35[[#This Row],[Mrp]]+$X$4), IF($S$3="nc", IF($T$3=1, Price35[[#This Row],[Net Cash]]+$W$5, Price35[[#This Row],[Net Cash]]+$X$5), IF($S$3="npc", IF($T$3=1, Price35[[#This Row],[Net Price Credit]]+$W$6, Price35[[#This Row],[Net Price Credit]]+$X$6), IF($S$3="w", IF($T$3=1, Price35[[#This Row],[Wsp]]+$W$6, Price35[[#This Row],[Wsp]]+$X$6), "")))), 10)) -> 1300
B31: 965 | C31: shawl | D31: Kashmiri | F31: shahtoosh | G31: 390 | I31: 165 | J31: =IF(SUMIF(G31:I31,"<>")=0,"",SUM(G31:I31)) -> 555 | K31: =IF(ISNUMBER(L31), IF(CEILING(ROUND(L31*0.95,2),5)=420, 425, CEILING(ROUND(L31*0.95,2),5) ), "" ) -> 715 | L31: =IF(ISNUMBER(J31), IF(CEILING(ROUND(J31*1.35,2),5)=420, 425, CEILING(ROUND(J31*1.35,2),5) ), "" ) -> 750 | M31: =IF(AND(ISNUMBER(J31),ISNUMBER(G31)), IF( CEILING( ROUND((J31*1.5) * IF(J31*1.5 <= 2500, 1.05, 1.18), 2), IF(ROUND((J31*1.5) * IF(J31*1.5 <= 2500, 1.05, 1.18), 2) < 2500, 25, 50) )=420, 425, CEILING( ROUND((J31*1.5) * IF(J31*1.5 <= 2500, 1.05, 1.18), 2), IF(ROUND((J31*1.5) * IF(J31*1.5 <= 2500, 1.05, 1.18), 2) < 2500, 25, 50) ) ), "" ) -> 875 | N31: =IF(ISNUMBER(G31), CEILING(ROUND(L31*0.92,2),5), "") -> 690 | O31: =IF(ISNUMBER(L31), IF(CEILING(ROUND(L31*1.07,2),5)=420, 425, CEILING(ROUND(L31*1.07,2),5) ), "" ) -> 805 | P31: =IF((((G31*1.5)+50)/0.835)<2500, MROUND(((((G31*1.5)+50)/0.835)*1.05)*2,10), MROUND(((((G31*1.5)+50)/0.835)*1.18)*2,10)) -> 1600 | Q31: =IF($S$3="","", MROUND( IF($S$3="m", IF($T$3=1, Price35[[#This Row],[Mrp]]+$W$4, Price35[[#This Row],[Mrp]]+$X$4), IF($S$3="nc", IF($T$3=1, Price35[[#This Row],[Net Cash]]+$W$5, Price35[[#This Row],[Net Cash]]+$X$5), IF($S$3="npc", IF($T$3=1, Price35[[#This Row],[Net Price Credit]]+$W$6, Price35[[#This Row],[Net Price Credit]]+$X$6), IF($S$3="w", IF($T$3=1, Price35[[#This Row],[Wsp]]+$W$6, Price35[[#This Row],[Wsp]]+$X$6), "")))), 10)) -> 950
B32: 968 | C32: shawl | D32: Kashmiri | F32: variety 14 no. | G32: 460 | I32: 310 | J32: =IF(SUMIF(G32:I32,"<>")=0,"",SUM(G32:I32)) -> 770 | K32: =IF(ISNUMBER(L32), IF(CEILING(ROUND(L32*0.95,2),5)=420, 425, CEILING(ROUND(L32*0.95,2),5) ), "" ) -> 990 | L32: =IF(ISNUMBER(J32), IF(CEILING(ROUND(J32*1.35,2),5)=420, 425, CEILING(ROUND(J32*1.35,2),5) ), "" ) -> 1040 | M32: =IF(AND(ISNUMBER(J32),ISNUMBER(G32)), IF( CEILING( ROUND((J32*1.5) * IF(J32*1.5 <= 2500, 1.05, 1.18), 2), IF(ROUND((J32*1.5) * IF(J32*1.5 <= 2500, 1.05, 1.18), 2) < 2500, 25, 50) )=420, 425, CEILING( ROUND((J32*1.5) * IF(J32*1.5 <= 2500, 1.05, 1.18), 2), IF(ROUND((J32*1.5) * IF(J32*1.5 <= 2500, 1.05, 1.18), 2) < 2500, 25, 50) ) ), "" ) -> 1225 | N32: =IF(ISNUMBER(G32), CEILING(ROUND(L32*0.92,2),5), "") -> 960 | O32: =IF(ISNUMBER(L32), IF(CEILING(ROUND(L32*1.07,2),5)=420, 425, CEILING(ROUND(L32*1.07,2),5) ), "" ) -> 1115 | P32: =IF((((G32*1.5)+50)/0.835)<2500, MROUND(((((G32*1.5)+50)/0.835)*1.05)*2,10), MROUND(((((G32*1.5)+50)/0.835)*1.18)*2,10)) -> 1860 | Q32: =IF($S$3="","", MROUND( IF($S$3="m", IF($T$3=1, Price35[[#This Row],[Mrp]]+$W$4, Price35[[#This Row],[Mrp]]+$X$4), IF($S$3="nc", IF($T$3=1, Price35[[#This Row],[Net Cash]]+$W$5, Price35[[#This Row],[Net Cash]]+$X$5), IF($S$3="npc", IF($T$3=1, Price35[[#This Row],[Net Price Credit]]+$W$6, Price35[[#This Row],[Net Price Credit]]+$X$6), IF($S$3="w", IF($T$3=1, Price35[[#This Row],[Wsp]]+$W$6, Price35[[#This Row],[Wsp]]+$X$6), "")))), 10)) -> 1300
B33: 969 | C33: shawl | D33: Kashmiri | F33: pipping variety | G33: 390 | I33: 210 | J33: =IF(SUMIF(G33:I33,"<>")=0,"",SUM(G33:I33)) -> 600 | K33: =IF(ISNUMBER(L33), IF(CEILING(ROUND(L33*0.95,2),5)=420, 425, CEILING(ROUND(L33*0.95,2),5) ), "" ) -> 770 | L33: =IF(ISNUMBER(J33), IF(CEILING(ROUND(J33*1.35,2),5)=420, 425, CEILING(ROUND(J33*1.35,2),5) ), "" ) -> 810 | M33: =IF(AND(ISNUMBER(J33),ISNUMBER(G33)), IF( CEILING( ROUND((J33*1.5) * IF(J33*1.5 <= 2500, 1.05, 1.18), 2), IF(ROUND((J33*1.5) * IF(J33*1.5 <= 2500, 1.05, 1.18), 2) < 2500, 25, 50) )=420, 425, CEILING( ROUND((J33*1.5) * IF(J33*1.5 <= 2500, 1.05, 1.18), 2), IF(ROUND((J33*1.5) * IF(J33*1.5 <= 2500, 1.05, 1.18), 2) < 2500, 25, 50) ) ), "" ) -> 950 | N33: =IF(ISNUMBER(G33), CEILING(ROUND(L33*0.92,2),5), "") -> 750 | O33: =IF(ISNUMBER(L33), IF(CEILING(ROUND(L33*1.07,2),5)=420, 425, CEILING(ROUND(L33*1.07,2),5) ), "" ) -> 870 | P33: =IF((((G33*1.5)+50)/0.835)<2500, MROUND(((((G33*1.5)+50)/0.835)*1.05)*2,10), MROUND(((((G33*1.5)+50)/0.835)*1.18)*2,10)) -> 1600 | Q33: =IF($S$3="","", MROUND( IF($S$3="m", IF($T$3=1, Price35[[#This Row],[Mrp]]+$W$4, Price35[[#This Row],[Mrp]]+$X$4), IF($S$3="nc", IF($T$3=1, Price35[[#This Row],[Net Cash]]+$W$5, Price35[[#This Row],[Net Cash]]+$X$5), IF($S$3="npc", IF($T$3=1, Price35[[#This Row],[Net Price Credit]]+$W$6, Price35[[#This Row],[Net Price Credit]]+$X$6), IF($S$3="w", IF($T$3=1, Price35[[#This Row],[Wsp]]+$W$6, Price35[[#This Row],[Wsp]]+$X$6), "")))), 10)) -> 1020
B34: 970 | C34: shawl | D34: Kashmiri | F34: jal | G34: 460 | I34: 375 | J34: =IF(SUMIF(G34:I34,"<>")=0,"",SUM(G34:I34)) -> 835 | K34: =IF(ISNUMBER(L34), IF(CEILING(ROUND(L34*0.95,2),5)=420, 425, CEILING(ROUND(L34*0.95,2),5) ), "" ) -> 1075 | L34: =IF(ISNUMBER(J34), IF(CEILING(ROUND(J34*1.35,2),5)=420, 425, CEILING(ROUND(J34*1.35,2),5) ), "" ) -> 1130 | M34: =IF(AND(ISNUMBER(J34),ISNUMBER(G34)), IF( CEILING( ROUND((J34*1.5) * IF(J34*1.5 <= 2500, 1.05, 1.18), 2), IF(ROUND((J34*1.5) * IF(J34*1.5 <= 2500, 1.05, 1.18), 2) < 2500, 25, 50) )=420, 425, CEILING( ROUND((J34*1.5) * IF(J34*1.5 <= 2500, 1.05, 1.18), 2), IF(ROUND((J34*1.5) * IF(J34*1.5 <= 2500, 1.05, 1.18), 2) < 2500, 25, 50) ) ), "" ) -> 1325 | N34: =IF(ISNUMBER(G34), CEILING(ROUND(L34*0.92,2),5), "") -> 1040 | O34: =IF(ISNUMBER(L34), IF(CEILING(ROUND(L34*1.07,2),5)=420, 425, CEILING(ROUND(L34*1.07,2),5) ), "" ) -> 1210 | P34: =IF((((G34*1.5)+50)/0.835)<2500, MROUND(((((G34*1.5)+50)/0.835)*1.05)*2,10), MROUND(((((G34*1.5)+50)/0.835)*1.18)*2,10)) -> 1860 | Q34: =IF($S$3="","", MROUND( IF($S$3="m", IF($T$3=1, Price35[[#This Row],[Mrp]]+$W$4, Price35[[#This Row],[Mrp]]+$X$4), IF($S$3="nc", IF($T$3=1, Price35[[#This Row],[Net Cash]]+$W$5, Price35[[#This Row],[Net Cash]]+$X$5), IF($S$3="npc", IF($T$3=1, Price35[[#This Row],[Net Price Credit]]+$W$6, Price35[[#This Row],[Net Price Credit]]+$X$6), IF($S$3="w", IF($T$3=1, Price35[[#This Row],[Wsp]]+$W$6, Price35[[#This Row],[Wsp]]+$X$6), "")))), 10)) -> 1400
B35: 971 | C35: shawl | D35: Kashmiri | F35: variety 13 no. | G35: 425 | I35: 210 | J35: =IF(SUMIF(G35:I35,"<>")=0,"",SUM(G35:I35)) -> 635 | K35: =IF(ISNUMBER(L35), IF(CEILING(ROUND(L35*0.95,2),5)=420, 425, CEILING(ROUND(L35*0.95,2),5) ), "" ) -> 820 | L35: =IF(ISNUMBER(J35), IF(CEILING(ROUND(J35*1.35,2),5)=420, 425, CEILING(ROUND(J35*1.35,2),5) ), "" ) -> 860 | M35: =IF(AND(ISNUMBER(J35),ISNUMBER(G35)), IF( CEILING( ROUND((J35*1.5) * IF(J35*1.5 <= 2500, 1.05, 1.18), 2), IF(ROUND((J35*1.5) * IF(J35*1.5 <= 2500, 1.05, 1.18), 2) < 2500, 25, 50) )=420, 425, CEILING( ROUND((J35*1.5) * IF(J35*1.5 <= 2500, 1.05, 1.18), 2), IF(ROUND((J35*1.5) * IF(J35*1.5 <= 2500, 1.05, 1.18), 2) < 2500, 25, 50) ) ), "" ) -> 1025 | N35: =IF(ISNUMBER(G35), CEILING(ROUND(L35*0.92,2),5), "") -> 795 | O35: =IF(ISNUMBER(L35), IF(CEILING(ROUND(L35*1.07,2),5)=420, 425, CEILING(ROUND(L35*1.07,2),5) ), "" ) -> 925 | P35: =IF((((G35*1.5)+50)/0.835)<2500, MROUND(((((G35*1.5)+50)/0.835)*1.05)*2,10), MROUND(((((G35*1.5)+50)/0.835)*1.18)*2,10)) -> 1730 | Q35: =IF($S$3="","", MROUND( IF($S$3="m", IF($T$3=1, Price35[[#This Row],[Mrp]]+$W$4, Price35[[#This Row],[Mrp]]+$X$4), IF($S$3="nc", IF($T$3=1, Price35[[#This Row],[Net Cash]]+$W$5, Price35[[#This Row],[Net Cash]]+$X$5), IF($S$3="npc", IF($T$3=1, Price35[[#This Row],[Net Price Credit]]+$W$6, Price35[[#This Row],[Net Price Credit]]+$X$6), IF($S$3="w", IF($T$3=1, Price35[[#This Row],[Wsp]]+$W$6, Price35[[#This Row],[Wsp]]+$X$6), "")))), 10)) -> 1100
B36: 973 | C36: shawl | D36: Kashmiri | F36: hashia variety | G36: 460 | I36: 340 | J36: =IF(SUMIF(G36:I36,"<>")=0,"",SUM(G36:I36)) -> 800 | K36: =IF(ISNUMBER(L36), IF(CEILING(ROUND(L36*0.95,2),5)=420, 425, CEILING(ROUND(L36*0.95,2),5) ), "" ) -> 1030 | L36: =IF(ISNUMBER(J36), IF(CEILING(ROUND(J36*1.35,2),5)=420, 425, CEILING(ROUND(J36*1.35,2),5) ), "" ) -> 1080 | M36: =IF(AND(ISNUMBER(J36),ISNUMBER(G36)), IF( CEILING( ROUND((J36*1.5) * IF(J36*1.5 <= 2500, 1.05, 1.18), 2), IF(ROUND((J36*1.5) * IF(J36*1.5 <= 2500, 1.05, 1.18), 2) < 2500, 25, 50) )=420, 425, CEILING( ROUND((J36*1.5) * IF(J36*1.5 <= 2500, 1.05, 1.18), 2), IF(ROUND((J36*1.5) * IF(J36*1.5 <= 2500, 1.05, 1.18), 2) < 2500, 25, 50) ) ), "" ) -> 1275 | N36: =IF(ISNUMBER(G36), CEILING(ROUND(L36*0.92,2),5), "") -> 995 | O36: =IF(ISNUMBER(L36), IF(CEILING(ROUND(L36*1.07,2),5)=420, 425, CEILING(ROUND(L36*1.07,2),5) ), "" ) -> 1160 | P36: =IF((((G36*1.5)+50)/0.835)<2500, MROUND(((((G36*1.5)+50)/0.835)*1.05)*2,10), MROUND(((((G36*1.5)+50)/0.835)*1.18)*2,10)) -> 1860 | Q36: =IF($S$3="","", MROUND( IF($S$3="m", IF($T$3=1, Price35[[#This Row],[Mrp]]+$W$4, Price35[[#This Row],[Mrp]]+$X$4), IF($S$3="nc", IF($T$3=1, Price35[[#This Row],[Net Cash]]+$W$5, Price35[[#This Row],[Net Cash]]+$X$5), IF($S$3="npc", IF($T$3=1, Price35[[#This Row],[Net Price Credit]]+$W$6, Price35[[#This Row],[Net Price Credit]]+$X$6), IF($S$3="w", IF($T$3=1, Price35[[#This Row],[Wsp]]+$W$6, Price35[[#This Row],[Wsp]]+$X$6), "")))), 10)) -> 1350
B37: 1004 | C37: shawl | D37: Kashmiri | F37: 2-4 b.r kingri | G37: 560 | I37: 145 | J37: =IF(SUMIF(G37:I37,"<>")=0,"",SUM(G37:I37)) -> 705 | K37: =IF(ISNUMBER(L37), IF(CEILING(ROUND(L37*0.95,2),5)=420, 425, CEILING(ROUND(L37*0.95,2),5) ), "" ) -> 910 | L37: =IF(ISNUMBER(J37), IF(CEILING(ROUND(J37*1.35,2),5)=420, 425, CEILING(ROUND(J37*1.35,2),5) ), "" ) -> 955 | M37: =IF(AND(ISNUMBER(J37),ISNUMBER(G37)), IF( CEILING( ROUND((J37*1.5) * IF(J37*1.5 <= 2500, 1.05, 1.18), 2), IF(ROUND((J37*1.5) * IF(J37*1.5 <= 2500, 1.05, 1.18), 2) < 2500, 25, 50) )=420, 425, CEILING( ROUND((J37*1.5) * IF(J37*1.5 <= 2500, 1.05, 1.18), 2), IF(ROUND((J37*1.5) * IF(J37*1.5 <= 2500, 1.05, 1.18), 2) < 2500, 25, 50) ) ), "" ) -> 1125 | N37: =IF(ISNUMBER(G37), CEILING(ROUND(L37*0.92,2),5), "") -> 880 | O37: =IF(ISNUMBER(L37), IF(CEILING(ROUND(L37*1.07,2),5)=420, 425, CEILING(ROUND(L37*1.07,2),5) ), "" ) -> 1025 | P37: =IF((((G37*1.5)+50)/0.835)<2500, MROUND(((((G37*1.5)+50)/0.835)*1.05)*2,10), MROUND(((((G37*1.5)+50)/0.835)*1.18)*2,10)) -> 2240 | Q37: =IF($S$3="","", MROUND( IF($S$3="m", IF($T$3=1, Price35[[#This Row],[Mrp]]+$W$4, Price35[[#This Row],[Mrp]]+$X$4), IF($S$3="nc", IF($T$3=1, Price35[[#This Row],[Net Cash]]+$W$5, Price35[[#This Row],[Net Cash]]+$X$5), IF($S$3="npc", IF($T$3=1, Price35[[#This Row],[Net Price Credit]]+$W$6, Price35[[#This Row],[Net Price Credit]]+$X$6), IF($S$3="w", IF($T$3=1, Price35[[#This Row],[Wsp]]+$W$6, Price35[[#This Row],[Wsp]]+$X$6), "")))), 10)) -> 1200
A38: 2026 | B38: 1005 | C38: shawl | D38: Kashmiri | E38: sharma | F38: shahtoosh multihead 45*90 | G38: 460 | I38: 300 | J38: =IF(SUMIF(G38:I38,"<>")=0,"",SUM(G38:I38)) -> 760 | K38: =IF(ISNUMBER(L38), IF(CEILING(ROUND(L38*0.95,2),5)=420, 425, CEILING(ROUND(L38*0.95,2),5) ), "" ) -> 980 | L38: =IF(ISNUMBER(J38), IF(CEILING(ROUND(J38*1.35,2),5)=420, 425, CEILING(ROUND(J38*1.35,2),5) ), "" ) -> 1030 | M38: =IF(AND(ISNUMBER(J38),ISNUMBER(G38)), IF( CEILING( ROUND((J38*1.5) * IF(J38*1.5 <= 2500, 1.05, 1.18), 2), IF(ROUND((J38*1.5) * IF(J38*1.5 <= 2500, 1.05, 1.18), 2) < 2500, 25, 50) )=420, 425, CEILING( ROUND((J38*1.5) * IF(J38*1.5 <= 2500, 1.05, 1.18), 2), IF(ROUND((J38*1.5) * IF(J38*1.5 <= 2500, 1.05, 1.18), 2) < 2500, 25, 50) ) ), "" ) -> 1200 | N38: =IF(ISNUMBER(G38), CEILING(ROUND(L38*0.92,2),5), "") -> 950 | O38: =IF(ISNUMBER(L38), IF(CEILING(ROUND(L38*1.07,2),5)=420, 425, CEILING(ROUND(L38*1.07,2),5) ), "" ) -> 1105 | P38: =IF((((G38*1.5)+50)/0.835)<2500, MROUND(((((G38*1.5)+50)/0.835)*1.05)*2,10), MROUND(((((G38*1.5)+50)/0.835)*1.18)*2,10)) -> 1860 | Q38: =IF($S$3="","", MROUND( IF($S$3="m", IF($T$3=1, Price35[[#This Row],[Mrp]]+$W$4, Price35[[#This Row],[Mrp]]+$X$4), IF($S$3="nc", IF($T$3=1, Price35[[#This Row],[Net Cash]]+$W$5, Price35[[#This Row],[Net Cash]]+$X$5), IF($S$3="npc", IF($T$3=1, Price35[[#This Row],[Net Price Credit]]+$W$6, Price35[[#This Row],[Net Price Credit]]+$X$6), IF($S$3="w", IF($T$3=1, Price35[[#This Row],[Wsp]]+$W$6, Price35[[#This Row],[Wsp]]+$X$6), "")))), 10)) -> 1270
A39: 2026 | B39: 1006 | C39: shawl | D39: Kashmiri | F39: 2-4 hashia multihead new | G39: 550 | I39: 400 | J39: =IF(SUMIF(G39:I39,"<>")=0,"",SUM(G39:I39)) -> 950 | K39: =IF(ISNUMBER(L39), IF(CEILING(ROUND(L39*0.95,2),5)=420, 425, CEILING(ROUND(L39*0.95,2),5) ), "" ) -> 1225 | L39: =IF(ISNUMBER(J39), IF(CEILING(ROUND(J39*1.35,2),5)=420, 425, CEILING(ROUND(J39*1.35,2),5) ), "" ) -> 1285 | M39: =IF(AND(ISNUMBER(J39),ISNUMBER(G39)), IF( CEILING( ROUND((J39*1.5) * IF(J39*1.5 <= 2500, 1.05, 1.18), 2), IF(ROUND((J39*1.5) * IF(J39*1.5 <= 2500, 1.05, 1.18), 2) < 2500, 25, 50) )=420, 425, CEILING( ROUND((J39*1.5) * IF(J39*1.5 <= 2500, 1.05, 1.18), 2), IF(ROUND((J39*1.5) * IF(J39*1.5 <= 2500, 1.05, 1.18), 2) < 2500, 25, 50) ) ), "" ) -> 1500 | N39: =IF(ISNUMBER(G39), CEILING(ROUND(L39*0.92,2),5), "") -> 1185 | O39: =IF(ISNUMBER(L39), IF(CEILING(ROUND(L39*1.07,2),5)=420, 425, CEILING(ROUND(L39*1.07,2),5) ), "" ) -> 1375 | P39: =IF((((G39*1.5)+50)/0.835)<2500, MROUND(((((G39*1.5)+50)/0.835)*1.05)*2,10), MROUND(((((G39*1.5)+50)/0.835)*1.18)*2,10)) -> 2200 | Q39: =IF($S$3="","", MROUND( IF($S$3="m", IF($T$3=1, Price35[[#This Row],[Mrp]]+$W$4, Price35[[#This Row],[Mrp]]+$X$4), IF($S$3="nc", IF($T$3=1, Price35[[#This Row],[Net Cash]]+$W$5, Price35[[#This Row],[Net Cash]]+$X$5), IF($S$3="npc", IF($T$3=1, Price35[[#This Row],[Net Price Credit]]+$W$6, Price35[[#This Row],[Net Price Credit]]+$X$6), IF($S$3="w", IF($T$3=1, Price35[[#This Row],[Wsp]]+$W$6, Price35[[#This Row],[Wsp]]+$X$6), "")))), 10)) -> 1570
B40: 1007 | C40: shawl | D40: Kashmiri | F40: 2-4 hashia | G40: 560 | I40: 210 | J40: =IF(SUMIF(G40:I40,"<>")=0,"",SUM(G40:I40)) -> 770 | K40: =IF(ISNUMBER(L40), IF(CEILING(ROUND(L40*0.95,2),5)=420, 425, CEILING(ROUND(L40*0.95,2),5) ), "" ) -> 990 | L40: =IF(ISNUMBER(J40), IF(CEILING(ROUND(J40*1.35,2),5)=420, 425, CEILING(ROUND(J40*1.35,2),5) ), "" ) -> 1040 | M40: =IF(AND(ISNUMBER(J40),ISNUMBER(G40)), IF( CEILING( ROUND((J40*1.5) * IF(J40*1.5 <= 2500, 1.05, 1.18), 2), IF(ROUND((J40*1.5) * IF(J40*1.5 <= 2500, 1.05, 1.18), 2) < 2500, 25, 50) )=420, 425, CEILING( ROUND((J40*1.5) * IF(J40*1.5 <= 2500, 1.05, 1.18), 2), IF(ROUND((J40*1.5) * IF(J40*1.5 <= 2500, 1.05, 1.18), 2) < 2500, 25, 50) ) ), "" ) -> 1225 | N40: =IF(ISNUMBER(G40), CEILING(ROUND(L40*0.92,2),5), "") -> 960 | O40: =IF(ISNUMBER(L40), IF(CEILING(ROUND(L40*1.07,2),5)=420, 425, CEILING(ROUND(L40*1.07,2),5) ), "" ) -> 1115 | P40: =IF((((G40*1.5)+50)/0.835)<2500, MROUND(((((G40*1.5)+50)/0.835)*1.05)*2,10), MROUND(((((G40*1.5)+50)/0.835)*1.18)*2,10)) -> 2240 | Q40: =IF($S$3="","", MROUND( IF($S$3="m", IF($T$3=1, Price35[[#This Row],[Mrp]]+$W$4, Price35[[#This Row],[Mrp]]+$X$4), IF($S$3="nc", IF($T$3=1, Price35[[#This Row],[Net Cash]]+$W$5, Price35[[#This Row],[Net Cash]]+$X$5), IF($S$3="npc", IF($T$3=1, Price35[[#This Row],[Net Price Credit]]+$W$6, Price35[[#This Row],[Net Price Credit]]+$X$6), IF($S$3="w", IF($T$3=1, Price35[[#This Row],[Wsp]]+$W$6, Price35[[#This Row],[Wsp]]+$X$6), "")))), 10)) -> 1300
B41: 1008 | C41: shawl | D41: Kashmiri | F41: hashia multihead 45 | G41: 460 | I41: 400 | J41: =IF(SUMIF(G41:I41,"<>")=0,"",SUM(G41:I41)) -> 860 | K41: =IF(ISNUMBER(L41), IF(CEILING(ROUND(L41*0.95,2),5)=420, 425, CEILING(ROUND(L41*0.95,2),5) ), "" ) -> 1110 | L41: =IF(ISNUMBER(J41), IF(CEILING(ROUND(J41*1.35,2),5)=420, 425, CEILING(ROUND(J41*1.35,2),5) ), "" ) -> 1165 | M41: =IF(AND(ISNUMBER(J41),ISNUMBER(G41)), IF( CEILING( ROUND((J41*1.5) * IF(J41*1.5 <= 2500, 1.05, 1.18), 2), IF(ROUND((J41*1.5) * IF(J41*1.5 <= 2500, 1.05, 1.18), 2) < 2500, 25, 50) )=420, 425, CEILING( ROUND((J41*1.5) * IF(J41*1.5 <= 2500, 1.05, 1.18), 2), IF(ROUND((J41*1.5) * IF(J41*1.5 <= 2500, 1.05, 1.18), 2) < 2500, 25, 50) ) ), "" ) -> 1375 | N41: =IF(ISNUMBER(G41), CEILING(ROUND(L41*0.92,2),5), "") -> 1075 | O41: =IF(ISNUMBER(L41), IF(CEILING(ROUND(L41*1.07,2),5)=420, 425, CEILING(ROUND(L41*1.07,2),5) ), "" ) -> 1250 | P41: =IF((((G41*1.5)+50)/0.835)<2500, MROUND(((((G41*1.5)+50)/0.835)*1.05)*2,10), MROUND(((((G41*1.5)+50)/0.835)*1.18)*2,10)) -> 1860 | Q41: =IF($S$3="","", MROUND( IF($S$3="m", IF($T$3=1, Price35[[#This Row],[Mrp]]+$W$4, Price35[[#This Row],[Mrp]]+$X$4), IF($S$3="nc", IF($T$3=1, Price35[[#This Row],[Net Cash]]+$W$5, Price35[[#This Row],[Net Cash]]+$X$5), IF($S$3="npc", IF($T$3=1, Price35[[#This Row],[Net Price Credit]]+$W$6, Price35[[#This Row],[Net Price Credit]]+$X$6), IF($S$3="w", IF($T$3=1, Price35[[#This Row],[Wsp]]+$W$6, Price35[[#This Row],[Wsp]]+$X$6), "")))), 10)) -> 1450
...

Sheet Full Price List
A1: Yom | B1: Art no. | C1: Item | D1: Quality | E1: Supplier | F1: Description | G1: Cost | H1: Increase | I1: Expenses | J1: Total Cost | K1: Net Price Credit | L1: Wsp | M1: Mrp | N1: Net Cash | O1: South | P1: Amazon
A2: 2025 | B2: 120 | C2: Lohi | D2: polywool | E2: m.r | F2: self lohi m.r | G2: 540 | I2: 25 | J2: 565 | K2: 675 | L2: 710 | M2: 900 | N2: 655 | O2: 760 | P2: 2160
B3: 121 | C3: Lohi | D3: Fine Wool | E3: Gaurav | F3: gents KANI GW jal pure | G3: 3350 | I3: 15 | J3: 3365 | K3: 4160 | L3: 4375 | M3: 6000 | N3: 4025 | O3: 4685 | P3: 14340
B4: 122 | C4: Lohi | D4: Fine Wool | E4: Maya | F4: gents kani polywool maya | G4: 1150 | I4: 15 | J4: 1165 | K4: 1440 | L4: 1515 | M4: 1850 | N4: 1395 | O4: 1625 | P4: 4460
A5: 2026 | B5: 123 | C5: Lohi | D5: Fine Wool | E5: Dh | F5: gents kani d.h | G5: 1525 | H5: 5 | I5: 15 | J5: 1545 | K5: 1910 | L5: 2010 | M5: 2450 | N5: 1850 | O5: 2155 | P5: 6610
